Workbook

Sheet Leia-me
A1: Melhorias incrementais — valores propostos
A2: Documento de regras: Docs/01_Design/39_Melhorias_incrementais_e_formigueiro_de_dependencias.md. Criado em 2026-10-19. Proposta sem balanceamento em jogo.
A4: Convenção de cores
A5: Texto azul = valor digitado (entrada que pode ser ajustada).
A6: Texto preto = fórmula (não digitar por cima).
A7: Texto verde = fórmula que puxa valor de outra aba.
A8: Fundo amarelo = premissa-chave de balanceamento (aba Parametros).
A10: Abas
A11: Parametros: crescimento do custo por tipo, marco de multiplicador, pontos e limites de profundidade.
A12: Camaras: nós únicos (desbloqueios) das duas abas, com requisitos e custo.
A13: Galerias: nós com nível; custo base, efeito por nível, teto e valores calculados.
A14: Curva: custo de cada nível (1 a 50) por galeria. Curva_acumulada: total gasto até o nível.
... A21: Origem dos números: custos das seções 18–28 do design (Docs/) e valores base do jogo (ColonySettings, RaidSettings, QueenTree em 2026-10-19); demais valores são propostas do agente.

Sheet Parametros
A1: Parâmetro | B1: Valor | C1: Nota
A2: r Físico | B2: 1.35 | C2: Crescimento do custo por nível nas galerias físicas (com teto).
A3: r Economia | B3: 1.15 | C3: Crescimento do custo por nível nas galerias de economia (infinitas).
A4: r Combate | B4: 1.22 | C4: Crescimento do custo por nível nas galerias de combate (infinitas).
A5: Intervalo do marco (níveis) | B5: 10 | C5: A cada N níveis, o bônus de economia/combate é multiplicado.
A6: Multiplicador do marco | B6: 1.5 | C6: Multiplica o bônus da própria galeria a cada marco.
A7: Nível de referência das infinitas | B7: 25 | C7: Nível usado para mostrar custo e valor das galerias sem teto.
A8: Pontos por câmara | B8: 1 | C8: Profundidade ganha por câmara comprada (iniciais não contam).
A9: Pontos por nível | B9: 1 | C9: Profundidade ganha por nível de galeria.
A10: Pontos por galeria completa | B10: 3 | C10: Bônus de profundidade ao atingir o teto.
A11: Profundidade A1 | B11: 0 | C11: Anel 1 aberto desde o início.
A12: Profundidade A2 | B12: 5 | C12: Anel 2.
A13: Profundidade A3 | B13: 20 | C13: Anel 3.
... A15: Limite de redução do custo da cria | B15: -0.4 | C15: Q+2 e N3 somados não passam disso.

Sheet Camaras
A1: Id | B1: Aba | C1: Ramo | D1: Anel | E1: Nome | F1: Requisitos (nós) | G1: Condição do mundo | H1: Efeito | I1: Custo (N) | J1: Origem do custo | K1: Situação no jogo (2026-10-19)
A2: P0 | B2: Formigueiro | C2: Centro | D2: Centro | E2: Postura | F2: — | H2: Sala da rainha | I2: 0 | J2: Seção 17 | K2: Inicial
A3: T0 | B3: Formigueiro | C3: Centro | D3: Centro | E3: Túnel comum | F3: — | H3: Túneis genéricos | I3: 0 | J3: Seção 17 | K3: Inicial
A4: C0 | B4: Formigueiro | C4: Cultivo | D4: A1 | E4: Cultivo inicial | F4: P0 | H4: Sala de nutrientes (canteiros) | I4: 0 | J4: Seção 18 | K4: Pincel livre → nó inicial
A5: C1 | B5: Formigueiro | C5: Cultivo | D5: A1 | E5: Canteiros organizados | F5: C0 | H5: Seção 18 | I5: 90 | J5: Seção 18 | K5: Árvore só exibição
A6: C2 | B6: Formigueiro | C6: Cultivo | D6: A2 | E6: Área de preparo | F6: C1 | H6: Seção 18 | I6: 180 | J6: Seção 18 | K6: Árvore só exibição
A7: C3 | B7: Formigueiro | C7: Cultivo | D7: A2 | E7: Cultivo produtivo | F7: C1 | H7: Seção 18 | I7: 200 | J7: Seção 18 | K7: Árvore só exibição
A8: C4 | B8: Formigueiro | C8: Cultivo | D8: A3 | E8: Cultivo integrado | F8: C2 e C3 | H8: Seção 18 | I8: 400 | J8: Seção 18 | K8: Árvore só exibição
A9: C5 | B9: Formigueiro | C9: Cultivo | D9: A4 | E9: Jardim da rainha | F9: C4 e J+1 Nv 10 | H9: Nutriente pronto a até 12 células da rainha conta direto no saldo | I9: 2500 | J9: Proposta 39 | K9: Novo
A10: B0 | B10: Formigueiro | C10: Berçário | D10: A1 | E10: Berçário inicial | F10: C0 | H10: Seção 19 | I10: 50 | J10: Seção 19 | K10: Árvore só exibição
A11: B1 | B11: Formigueiro | C11: Berçário | D11: A2 | E11: Leitos de criação | F11: B0 | H11: Seção 19 | I11: 110 | J11: Seção 19 | K11: Árvore só exibição
A12: B2 | B12: Formigueiro | C12: Berçário | D12: A2 | E12: Área de maturação | F12: B0 | H12: Seção 19 | I12: 110 | J12: Seção 19 | K12: Árvore só exibição
A13: B3 | B13: Formigueiro | C13: Berçário | D13: A3 | E13: Berçário organizado | F13: B1 e B2 | H13: Seção 19 | I13: 260 | J13: Seção 19 | K13: Árvore só exibição
... A29: X1 | B29: Formigueiro | C29: Exterior | D29: A3 | E29: Jardim cultivado | F29: X+1 Nv 10 e J1 | H29: Plantas cortadas perto da entrada rebrotam no lugar | I29: 800 | J29: Proposta 39 | K29: Novo
A30: M0 | B30: Formigueiro | C30: Defesa | D30: A2 | E30: Entradas vigiadas | F30: T0 | G30: Primeiro ataque vencido | H30: Aviso de ataque 8 → 12 s | I30: 250 | J30: Proposta 39 | K30: Novo
A31: M1 | B31: Formigueiro | C31: Defesa | D31: A3 | E31: Câmara de refúgio | F31: M0, B3 e N2 | G31: 5 ataques vencidos | H31: Pincel de refúgio para crias e cuidadoras no aviso | I31: 900 | J31: Proposta 39 | K31: Novo
A32: Q0 | B32: Rainha | C32: Rainha | D32: Centro | E32: Postura inicial | F32: — | H32: Seção 23 | I32: 0 | J32: QueenTree | K32: Inicial
A33: Q1 | B33: Rainha | C33: Rainha | D33: A1 | E33: Postura acelerada | F33: Q0 | H33: 18 s → 12 s por ciclo | I33: 150 | J33: QueenTree | K33: Implementado
A34: Q2 | B34: Rainha | C34: Rainha | D34: A2 | E34: Postura em lotes | F34: Q1 e B0 | H34: Até 3 ovos por ciclo | I34: 450 | J34: QueenTree | K34: Implementado; B0 é requisito novo
A35: Q3 | B35: Rainha | C35: Rainha | D35: A4 | E35: Postura em campo | F35: Q2, B3 e Q+1 Nv 10 | H35: Põe ovos também nos trabalhos Coletar e Nutrientes | I35: 2400 | J35: Proposta 39 | K35: Novo
A36: O0 | B36: Rainha | C36: Comum | D36: Centro | E36: Operária comum | F36: — | H36: Seção 23 | I36: 0 | J36: QueenTree | K36: Inicial
A37: O1 | B37: Rainha | C37: Comum | D37: A1 | E37: Carga ampliada | F37: O0 | H37: 2 → 3 UM | I37: 100 | J37: QueenTree | K37: Implementado
A38: O2 | B38: Rainha | C38: Comum | D38: A1 | E38: Deslocamento rápido | F38: O0 | H38: 24 → 30 células/s | I38: 100 | J38: QueenTree | K38: Implementado
A39: O3 | B39: Rainha | C39: Comum | D39: A1 | E39: Retirada de companheiras | F39: O0 | H39: Seção 23 | I39: 240 | J39: QueenTree | K39: EM BREVE
A40: O4 | B40: Rainha | C40: Comum | D40: A4 | E40: Operária versátil | F40: O+1 Nv 10 e O+3 Nv 10 | G40: 50 adultas | H40: Sem especialista por perto, a comum faz a tarefa com metade do bônus | I40: 2000 | J40: Proposta 39 | K40: Novo
A41: L0 | B41: Rainha | C41: Carregadora | D41: A1 | E41: Carregadora | F41: O0 | H41: Libera a classe | I41: 140 | J41: QueenTree | K41: Implementado
A42: L1 | B42: Rainha | C42: Carregadora | D42: A2 | E42: Cargas maiores | F42: L0 | H42: 4 → 6 UM | I42: 160 | J42: QueenTree | K42: Implementado
A43: L2 | B43: Rainha | C43: Carregadora | D43: A3 | E43: Transporte cooperativo | F43: L1 e D1 | H43: Seção 24 | I43: 300 | J43: QueenTree | K43: EM BREVE; D1 é requisito novo
A44: L3 | B44: Rainha | C44: Carregadora | D44: A2 | E44: Velocidade das carregadoras | F44: L0 | H44: 28 → 35 células/s | I44: 200 | J44: QueenTree | K44: Implementado
A45: L4 | B45: Rainha | C45: Carregadora | D45: A4 | E45: Comboio | F45: L2 e D2 | H45: Grupos levam peça grande inteira ao depósito | I45: 1800 | J45: Proposta 39 | K45: Novo
A46: F0 | B46: Rainha | C46: Cortadeira | D46: A1 | E46: Cortadeira | F46: O0 | H46: Libera a classe | I46: 160 | J46: QueenTree | K46: Implementado
A47: F1 | B47: Rainha | C47: Cortadeira | D47: A2 | E47: Cortes maiores | F47: F0 | H47: Seção 24 | I47: 220 | J47: QueenTree | K47: Implementado
A48: F2 | B48: Rainha | C48: Cortadeira | D48: A3 | E48: Poda seletiva | F48: F1 e X+1 Nv 5 | H48: Planta cortada por cortadeira rebrota 50% mais rápido | I48: 600 | J48: Proposta 39 | K48: Novo
A49: E0 | B49: Rainha | C49: Escavadora | D49: A1 | E49: Escavadora | F49: O0 | H49: Libera a classe | I49: 180 | J49: QueenTree | K49: Implementado
A50: E1 | B50: Rainha | C50: Escavadora | D50: A2 | E50: Remoção ampliada | F50: E0 | H50: 32 → 48 células/s | I50: 200 | J50: QueenTree | K50: Implementado
A51: E2 | B51: Rainha | C51: Escavadora | D51: A3 | E51: Quebra de rocha | F51: E1 e T+2 Nv 3 | H51: Quebra rocha | I51: 400 | J51: QueenTree | K51: Implementado; T+2 é requisito novo
A52: E3 | B52: Rainha | C52: Escavadora | D52: A4 | E52: Frente larga | F52: E+1 Nv 10 e T2 | H52: Tira 2 células vizinhas por carga | I52: 1800 | J52: Proposta 39 | K52: Novo
... A60: N3 | B60: Rainha | C60: Cuidadora | D60: A3 | E60: Ama de leite | F60: N1 e Q+2 Nv 5 | H60: Custo da cria −10% (limite total −40% com Q+2) | I60: 700 | J60: Proposta 39 | K60: Novo
A61: S0 | B61: Rainha | C61: Soldado | D61: A2 | E61: Soldado | F61: O0 | G61: Primeiro ataque vencido | H61: Libera a classe | I61: 220 | J61: QueenTree | K61: Implementado
A62: S1 | B62: Rainha | C62: Soldado | D62: A2 | E62: Mandíbulas fortes | F62: S0 | H62: Dano 3 → 4,5/s | I62: 220 | J62: QueenTree | K62: Implementado
...

Sheet Galerias
A1: Id | B1: Aba | C1: Ramo | D1: Anel | E1: Nome | F1: Requisitos | G1: Atributo | H1: Base no jogo | I1: Unidade | J1: Efeito por nível | K1: Modo | L1: Tipo | M1: Teto (vazio = ∞) | N1: Custo base (N) | O1: r | P1: Nível de referência | Q1: Custo do nível 10 | R1: Custo total até o nível de referência | S1: Marco (multiplicador) no nível de referência | T1: Valor no nível de referência | U1: Marco Nv 25 | V1: Sistema existe hoje?
A2: H+1 | B2: Formigueiro | C2: Centro | D2: A1 | E2: Câmara real ampliada | F2: P0 | G2: Células por vaga adulta | H2: 24 | I2: células | J2: -0.04 | K2: % | L2: Físico | M2: 10 | N2: 60 | O2: =IF(L2="Físico",Parametros!$B$2,IF(L2="Economia",Parametros!$B$3,Parametros!$B$4)) | P2: =IF(M2="",Parametros!$B$7,M2) | Q2: =IF(AND(M2<>"",M2<10),"",ROUND(N2*O2^9,0)) | R2: =ROUND(N2*(O2^P2-1)/(O2-1),0) | S2: =IF(L2="Físico",1,Parametros!$B$6^INT(P2/Parametros!$B$5)) | T2: =IF(K2="%",H2*(1+J2*P2*S2),H2+J2*P2) | V2: Sim (CellsPerAdultSlot)
A3: C+1 | B3: Formigueiro | C3: Cultivo | D3: A1 | E3: Fungo vigoroso | F3: C1 | G3: Crescimento do canteiro | H3: 1 | I3: × base | J3: 0.08 | K3: % | L3: Economia | N3: 40 | O3: =IF(L3="Físico",Parametros!$B$2,IF(L3="Economia",Parametros!$B$3,Parametros!$B$4)) | P3: =IF(M3="",Parametros!$B$7,M3) | Q3: =IF(AND(M3<>"",M3<10),"",ROUND(N3*O3^9,0)) | R3: =ROUND(N3*(O3^P3-1)/(O3-1),0) | S3: =IF(L3="Físico",1,Parametros!$B$6^INT(P3/Parametros!$B$5)) | T3: =IF(K3="%",H3*(1+J3*P3*S3),H3+J3*P3) | U3: Canteiro novo já brota com 1 nutriente pronto | V3: Sim (crescimento dos canteiros)
A4: C+2 | B4: Formigueiro | C4: Cultivo | D4: A2 | E4: Colheita nutritiva | F4: C3 | G4: N por nutriente entregue | H4: 1 | I4: N | J4: 0.05 | K4: % | L4: Economia | N4: 120 | O4: =IF(L4="Físico",Parametros!$B$2,IF(L4="Economia",Parametros!$B$3,Parametros!$B$4)) | P4: =IF(M4="",Parametros!$B$7,M4) | Q4: =IF(AND(M4<>"",M4<10),"",ROUND(N4*O4^9,0)) | R4: =ROUND(N4*(O4^P4-1)/(O4-1),0) | S4: =IF(L4="Físico",1,Parametros!$B$6^INT(P4/Parametros!$B$5)) | T4: =IF(K4="%",H4*(1+J4*P4*S4),H4+J4*P4) | U4: 5% das entregas valem o dobro | V4: Sim (+1 N por entrega; precisa acumular fração)
A5: C+3 | B5: Formigueiro | C5: Cultivo | D5: A2 | E5: Cura rápida | F5: C+1 Nv 5 | G5: Tempo de cura do nutriente | H5: 30 | I5: s | J5: -0.04 | K5: % | L5: Físico | M5: 10 | N5: 150 | O5: =IF(L5="Físico",Parametros!$B$2,IF(L5="Economia",Parametros!$B$3,Parametros!$B$4)) | P5: =IF(M5="",Parametros!$B$7,M5) | Q5: =IF(AND(M5<>"",M5<10),"",ROUND(N5*O5^9,0)) | R5: =ROUND(N5*(O5^P5-1)/(O5-1),0) | S5: =IF(L5="Físico",1,Parametros!$B$6^INT(P5/Parametros!$B$5)) | T5: =IF(K5="%",H5*(1+J5*P5*S5),H5+J5*P5) | V5: Sim (NutrientCureSeconds)
A6: B+1 | B6: Formigueiro | C6: Berçário | D6: A3 | E6: Leitos aquecidos | F6: B3 | G6: Tempo de larva (14 s) e pupa (12 s) | H6: 14 | I6: s (larva) | J6: -0.03 | K6: % | L6: Físico | M6: 10 | N6: 250 | O6: =IF(L6="Físico",Parametros!$B$2,IF(L6="Economia",Parametros!$B$3,Parametros!$B$4)) | P6: =IF(M6="",Parametros!$B$7,M6) | Q6: =IF(AND(M6<>"",M6<10),"",ROUND(N6*O6^9,0)) | R6: =ROUND(N6*(O6^P6-1)/(O6-1),0) | S6: =IF(L6="Físico",1,Parametros!$B$6^INT(P6/Parametros!$B$5)) | T6: =IF(K6="%",H6*(1+J6*P6*S6),H6+J6*P6) | V6: Sim (LarvaSeconds, PupaSeconds)
A7: B+2 | B7: Formigueiro | C7: Berçário | D7: A3 | E7: Vagas extras | F7: B3 e H+1 Nv 3 | G7: Células por vaga de cria | H7: 16 | I7: células | J7: -0.05 | K7: % | L7: Físico | M7: 8 | N7: 250 | O7: =IF(L7="Físico",Parametros!$B$2,IF(L7="Economia",Parametros!$B$3,Parametros!$B$4)) | P7: =IF(M7="",Parametros!$B$7,M7) | Q7: =IF(AND(M7<>"",M7<10),"",ROUND(N7*O7^9,0)) | R7: =ROUND(N7*(O7^P7-1)/(O7-1),0) | S7: =IF(L7="Físico",1,Parametros!$B$6^INT(P7/Parametros!$B$5)) | T7: =IF(K7="%",H7*(1+J7*P7*S7),H7+J7*P7) | V7: Sim (CellsPerNurserySlot)
A8: D+1 | B8: Formigueiro | C8: Depósito | D8: A2 | E8: Empilhamento | F8: D1 | G8: Itens por célula de depósito | H8: 1 | I8: itens | J8: 0.25 | K8: % | L8: Físico | M8: 8 | N8: 120 | O8: =IF(L8="Físico",Parametros!$B$2,IF(L8="Economia",Parametros!$B$3,Parametros!$B$4)) | P8: =IF(M8="",Parametros!$B$7,M8) | Q8: =IF(AND(M8<>"",M8<10),"",ROUND(N8*O8^9,0)) | R8: =ROUND(N8*(O8^P8-1)/(O8-1),0) | S8: =IF(L8="Físico",1,Parametros!$B$6^INT(P8/Parametros!$B$5)) | T8: =IF(K8="%",H8*(1+J8*P8*S8),H8+J8*P8) | V8: Não (hoje 1 item por célula)
A9: D+2 | B9: Formigueiro | C9: Depósito | D9: A3 | E9: Conservação | F9: D1 e R0 | G9: Deterioração no depósito de alimentos | H9: 1 | I9: × base | J9: -0.05 | K9: % | L9: Físico | M9: 10 | N9: 250 | O9: =IF(L9="Físico",Parametros!$B$2,IF(L9="Economia",Parametros!$B$3,Parametros!$B$4)) | P9: =IF(M9="",Parametros!$B$7,M9) | Q9: =IF(AND(M9<>"",M9<10),"",ROUND(N9*O9^9,0)) | R9: =ROUND(N9*(O9^P9-1)/(O9-1),0) | S9: =IF(L9="Físico",1,Parametros!$B$6^INT(P9/Parametros!$B$5)) | T9: =IF(K9="%",H9*(1+J9*P9*S9),H9+J9*P9) | V9: Depende da perecibilidade (seção 09)
A10: G+1 | B10: Formigueiro | C10: Orvalho | D10: A2 | E10: Orvalho farto | F10: G0 | G10: Intervalo da gota | H10: 8 | I10: s | J10: -0.05 | K10: % | L10: Físico | M10: 10 | N10: 90 | O10: =IF(L10="Físico",Parametros!$B$2,IF(L10="Economia",Parametros!$B$3,Parametros!$B$4)) | P10: =IF(M10="",Parametros!$B$7,M10) | Q10: =IF(AND(M10<>"",M10<10),"",ROUND(N10*O10^9,0)) | R10: =ROUND(N10*(O10^P10-1)/(O10-1),0) | S10: =IF(L10="Físico",1,Parametros!$B$6^INT(P10/Parametros!$B$5)) | T10: =IF(K10="%",H10*(1+J10*P10*S10),H10+J10*P10) | V10: Sim (DewDropSeconds)
A11: G+2 | B11: Formigueiro | C11: Orvalho | D11: A2 | E11: Reservatório | F11: G1 | G11: Água máxima na sala | H11: 24 | I11: células | J11: 4 | K11: abs | L11: Físico | M11: 10 | N11: 120 | O11: =IF(L11="Físico",Parametros!$B$2,IF(L11="Economia",Parametros!$B$3,Parametros!$B$4)) | P11: =IF(M11="",Parametros!$B$7,M11) | Q11: =IF(AND(M11<>"",M11<10),"",ROUND(N11*O11^9,0)) | R11: =ROUND(N11*(O11^P11-1)/(O11-1),0) | S11: =IF(L11="Físico",1,Parametros!$B$6^INT(P11/Parametros!$B$5)) | T11: =IF(K11="%",H11*(1+J11*P11*S11),H11+J11*P11) | V11: Sim (DewMaxRoomWater)
A12: T+1 | B12: Formigueiro | C12: Obra | D12: A1 | E12: Obra barata | F12: T0 | G12: Tarifa de pintura | H12: 1 | I12: × base | J12: -0.03 | K12: % | L12: Físico | M12: 15 | N12: 50 | O12: =IF(L12="Físico",Parametros!$B$2,IF(L12="Economia",Parametros!$B$3,Parametros!$B$4)) | P12: =IF(M12="",Parametros!$B$7,M12) | Q12: =IF(AND(M12<>"",M12<10),"",ROUND(N12*O12^9,0)) | R12: =ROUND(N12*(O12^P12-1)/(O12-1),0) | S12: =IF(L12="Físico",1,Parametros!$B$6^INT(P12/Parametros!$B$5)) | T12: =IF(K12="%",H12*(1+J12*P12*S12),H12+J12*P12) | V12: Depende da tarifa de pintura (seção 03)
A13: T+2 | B13: Formigueiro | C13: Obra | D13: A2 | E13: Frentes de obra | F13: T1 e E0 | G13: Tempo de escavação de todas as classes | H13: 1 | I13: × base | J13: -0.03 | K13: % | L13: Físico | M13: 10 | N13: 150 | O13: =IF(L13="Físico",Parametros!$B$2,IF(L13="Economia",Parametros!$B$3,Parametros!$B$4)) | P13: =IF(M13="",Parametros!$B$7,M13) | Q13: =IF(AND(M13<>"",M13<10),"",ROUND(N13*O13^9,0)) | R13: =ROUND(N13*(O13^P13-1)/(O13-1),0) | S13: =IF(L13="Físico",1,Parametros!$B$6^INT(P13/Parametros!$B$5)) | T13: =IF(K13="%",H13*(1+J13*P13*S13),H13+J13*P13) | V13: Sim (DigTimeMultiplier)
A14: X+1 | B14: Formigueiro | C14: Exterior | D14: A2 | E14: Brotação | F14: X0 | G14: Crescimento das plantas de fora | H14: 1 | I14: × base | J14: 0.06 | K14: % | L14: Economia | N14: 100 | O14: =IF(L14="Físico",Parametros!$B$2,IF(L14="Economia",Parametros!$B$3,Parametros!$B$4)) | P14: =IF(M14="",Parametros!$B$7,M14) | Q14: =IF(AND(M14<>"",M14<10),"",ROUND(N14*O14^9,0)) | R14: =ROUND(N14*(O14^P14-1)/(O14-1),0) | S14: =IF(L14="Físico",1,Parametros!$B$6^INT(P14/Parametros!$B$5)) | T14: =IF(K14="%",H14*(1+J14*P14*S14),H14+J14*P14) | U14: Planta nova perto da entrada a cada 60 s | V14: Sim (vegetação)
A15: X+2 | B15: Formigueiro | C15: Exterior | D15: A2 | E15: Feromônio de trilha | F15: X0 | G15: Velocidade fora do formigueiro | H15: 1 | I15: × base | J15: 0.03 | K15: % | L15: Físico | M15: 10 | N15: 90 | O15: =IF(L15="Físico",Parametros!$B$2,IF(L15="Economia",Parametros!$B$3,Parametros!$B$4)) | P15: =IF(M15="",Parametros!$B$7,M15) | Q15: =IF(AND(M15<>"",M15<10),"",ROUND(N15*O15^9,0)) | R15: =ROUND(N15*(O15^P15-1)/(O15-1),0) | S15: =IF(L15="Físico",1,Parametros!$B$6^INT(P15/Parametros!$B$5)) | T15: =IF(K15="%",H15*(1+J15*P15*S15),H15+J15*P15) | V15: Sim (velocidade)
A16: X+3 | B16: Formigueiro | C16: Exterior | D16: A2 | E16: Faro | F16: X0 e F0 | G16: Raio de busca de planta | H16: 1 | I16: × base | J16: 0.05 | K16: % | L16: Físico | M16: 10 | N16: 100 | O16: =IF(L16="Físico",Parametros!$B$2,IF(L16="Economia",Parametros!$B$3,Parametros!$B$4)) | P16: =IF(M16="",Parametros!$B$7,M16) | Q16: =IF(AND(M16<>"",M16<10),"",ROUND(N16*O16^9,0)) | R16: =ROUND(N16*(O16^P16-1)/(O16-1),0) | S16: =IF(L16="Físico",1,Parametros!$B$6^INT(P16/Parametros!$B$5)) | T16: =IF(K16="%",H16*(1+J16*P16*S16),H16+J16*P16) | V16: Sim (planta-alvo)
A17: M+1 | B17: Formigueiro | C17: Defesa | D17: A2 | E17: Paredes reforçadas | F17: M0 | G17: Tempo do cupim para destruir parede | H17: 0.8 | I17: s | J17: 0.1 | K17: % | L17: Físico | M17: 10 | N17: 150 | O17: =IF(L17="Físico",Parametros!$B$2,IF(L17="Economia",Parametros!$B$3,Parametros!$B$4)) | P17: =IF(M17="",Parametros!$B$7,M17) | Q17: =IF(AND(M17<>"",M17<10),"",ROUND(N17*O17^9,0)) | R17: =ROUND(N17*(O17^P17-1)/(O17-1),0) | S17: =IF(L17="Físico",1,Parametros!$B$6^INT(P17/Parametros!$B$5)) | T17: =IF(K17="%",H17*(1+J17*P17*S17),H17+J17*P17) | V17: Sim (DestroySeconds)
A18: M+2 | B18: Formigueiro | C18: Defesa | D18: A2 | E18: Vigias | F18: M0 | G18: Aviso de ataque | H18: 8 | I18: s | J18: 1 | K18: abs | L18: Físico | M18: 8 | N18: 120 | O18: =IF(L18="Físico",Parametros!$B$2,IF(L18="Economia",Parametros!$B$3,Parametros!$B$4)) | P18: =IF(M18="",Parametros!$B$7,M18) | Q18: =IF(AND(M18<>"",M18<10),"",ROUND(N18*O18^9,0)) | R18: =ROUND(N18*(O18^P18-1)/(O18-1),0) | S18: =IF(L18="Físico",1,Parametros!$B$6^INT(P18/Parametros!$B$5)) | T18: =IF(K18="%",H18*(1+J18*P18*S18),H18+J18*P18) | V18: Sim (WarningSeconds)
A19: Q+1 | B19: Rainha | C19: Rainha | D19: A2 | E19: Fertilidade | F19: Q1 | G19: Intervalo de postura (com Q1) | H19: 12 | I19: s | J19: -0.03 | K19: % | L19: Físico | M19: 10 | N19: 200 | O19: =IF(L19="Físico",Parametros!$B$2,IF(L19="Economia",Parametros!$B$3,Parametros!$B$4)) | P19: =IF(M19="",Parametros!$B$7,M19) | Q19: =IF(AND(M19<>"",M19<10),"",ROUND(N19*O19^9,0)) | R19: =ROUND(N19*(O19^P19-1)/(O19-1),0) | S19: =IF(L19="Físico",1,Parametros!$B$6^INT(P19/Parametros!$B$5)) | T19: =IF(K19="%",H19*(1+J19*P19*S19),H19+J19*P19) | V19: Sim (LayIntervalSeconds)
A20: Q+2 | B20: Rainha | C20: Rainha | D20: A1 | E20: Geleia real | F20: Q0 e B0 | G20: Custo alimentar da cria | H20: 1 | I20: × base | J20: -0.02 | K20: % | L20: Físico | M20: 15 | N20: 150 | O20: =IF(L20="Físico",Parametros!$B$2,IF(L20="Economia",Parametros!$B$3,Parametros!$B$4)) | P20: =IF(M20="",Parametros!$B$7,M20) | Q20: =IF(AND(M20<>"",M20<10),"",ROUND(N20*O20^9,0)) | R20: =ROUND(N20*(O20^P20-1)/(O20-1),0) | S20: =IF(L20="Físico",1,Parametros!$B$6^INT(P20/Parametros!$B$5)) | T20: =IF(K20="%",H20*(1+J20*P20*S20),H20+J20*P20) | V20: Sim (AntRoles.FoodCost)
A21: Q+3 | B21: Rainha | C21: Rainha | D21: A1 | E21: Vigor real | F21: Q0 e primeiro ataque | G21: Vida da rainha | H21: 60 | I21: vida | J21: 0.1 | K21: % | L21: Físico | M21: 10 | N21: 250 | O21: =IF(L21="Físico",Parametros!$B$2,IF(L21="Economia",Parametros!$B$3,Parametros!$B$4)) | P21: =IF(M21="",Parametros!$B$7,M21) | Q21: =IF(AND(M21<>"",M21<10),"",ROUND(N21*O21^9,0)) | R21: =ROUND(N21*(O21^P21-1)/(O21-1),0) | S21: =IF(L21="Físico",1,Parametros!$B$6^INT(P21/Parametros!$B$5)) | T21: =IF(K21="%",H21*(1+J21*P21*S21),H21+J21*P21) | V21: Sim (QueenHealth)
A22: O+1 | B22: Rainha | C22: Comum | D22: A2 | E22: Passo firme | F22: O2 | G22: Velocidade das comuns (com O2) | H22: 30 | I22: células/s | J22: 0.04 | K22: % | L22: Físico | M22: 10 | N22: 80 | O22: =IF(L22="Físico",Parametros!$B$2,IF(L22="Economia",Parametros!$B$3,Parametros!$B$4)) | P22: =IF(M22="",Parametros!$B$7,M22) | Q22: =IF(AND(M22<>"",M22<10),"",ROUND(N22*O22^9,0)) | R22: =ROUND(N22*(O22^P22-1)/(O22-1),0) | S22: =IF(L22="Físico",1,Parametros!$B$6^INT(P22/Parametros!$B$5)) | T22: =IF(K22="%",H22*(1+J22*P22*S22),H22+J22*P22) | V22: Sim (QueenTree.SpeedFactor)
A23: O+2 | B23: Rainha | C23: Comum | D23: A1 | E23: Longevidade | F23: O0 e B1 | G23: Vida das adultas | H23: 600 | I23: s | J23: 0.1 | K23: % | L23: Físico | M23: 10 | N23: 150 | O23: =IF(L23="Físico",Parametros!$B$2,IF(L23="Economia",Parametros!$B$3,Parametros!$B$4)) | P23: =IF(M23="",Parametros!$B$7,M23) | Q23: =IF(AND(M23<>"",M23<10),"",ROUND(N23*O23^9,0)) | R23: =ROUND(N23*(O23^P23-1)/(O23-1),0) | S23: =IF(L23="Físico",1,Parametros!$B$6^INT(P23/Parametros!$B$5)) | T23: =IF(K23="%",H23*(1+J23*P23*S23),H23+J23*P23) | V23: Sim (AntLifespanSeconds)
A24: O+3 | B24: Rainha | C24: Comum | D24: A2 | E24: Mandíbula de trabalho | F24: O1 | G24: Tempo de corte das comuns | H24: 1 | I24: × base | J24: -0.03 | K24: % | L24: Físico | M24: 10 | N24: 80 | O24: =IF(L24="Físico",Parametros!$B$2,IF(L24="Economia",Parametros!$B$3,Parametros!$B$4)) | P24: =IF(M24="",Parametros!$B$7,M24) | Q24: =IF(AND(M24<>"",M24<10),"",ROUND(N24*O24^9,0)) | R24: =ROUND(N24*(O24^P24-1)/(O24-1),0) | S24: =IF(L24="Físico",1,Parametros!$B$6^INT(P24/Parametros!$B$5)) | T24: =IF(K24="%",H24*(1+J24*P24*S24),H24+J24*P24) | V24: Sim (corte)
A25: L+1 | B25: Rainha | C25: Carregadora | D25: A2 | E25: Costas largas | F25: L1 | G25: Carga da carregadora (com L1) | H25: 6 | I25: UM | J25: 1 | K25: abs | L25: Físico | M25: 4 | N25: 200 | O25: =IF(L25="Físico",Parametros!$B$2,IF(L25="Economia",Parametros!$B$3,Parametros!$B$4)) | P25: =IF(M25="",Parametros!$B$7,M25) | Q25: =IF(AND(M25<>"",M25<10),"",ROUND(N25*O25^9,0)) | R25: =ROUND(N25*(O25^P25-1)/(O25-1),0) | S25: =IF(L25="Físico",1,Parametros!$B$6^INT(P25/Parametros!$B$5)) | T25: =IF(K25="%",H25*(1+J25*P25*S25),H25+J25*P25) | V25: Sim (MaterialCapacity)
A26: L+2 | B26: Rainha | C26: Carregadora | D26: A2 | E26: Passo de carga | F26: L3 | G26: Velocidade das carregadoras (com L3) | H26: 35 | I26: células/s | J26: 0.04 | K26: % | L26: Físico | M26: 10 | N26: 120 | O26: =IF(L26="Físico",Parametros!$B$2,IF(L26="Economia",Parametros!$B$3,Parametros!$B$4)) | P26: =IF(M26="",Parametros!$B$7,M26) | Q26: =IF(AND(M26<>"",M26<10),"",ROUND(N26*O26^9,0)) | R26: =ROUND(N26*(O26^P26-1)/(O26-1),0) | S26: =IF(L26="Físico",1,Parametros!$B$6^INT(P26/Parametros!$B$5)) | T26: =IF(K26="%",H26*(1+J26*P26*S26),H26+J26*P26) | V26: Sim (QueenTree.SpeedFactor)
... A30: E+3 | B30: Rainha | C30: Escavadora | D30: A3 | E30: Britador | F30: E2 | G30: Tempo para quebrar rocha | H30: 1 | I30: s | J30: -0.06 | K30: % | L30: Físico | M30: 8 | N30: 300 | O30: =IF(L30="Físico",Parametros!$B$2,IF(L30="Economia",Parametros!$B$3,Parametros!$B$4)) | P30: =IF(M30="",Parametros!$B$7,M30) | Q30: =IF(AND(M30<>"",M30<10),"",ROUND(N30*O30^9,0)) | R30: =ROUND(N30*(O30^P30-1)/(O30-1),0) | S30: =IF(L30="Físico",1,Parametros!$B$6^INT(P30/Parametros!$B$5)) | T30: =IF(K30="%",H30*(1+J30*P30*S30),H30+J30*P30) | V30: Sim (RockBreakSeconds)
A31: J+1 | B31: Rainha | C31: Jardineira | D31: A2 | E31: Mãos verdes | F31: J1 | G31: Bônus da jardineira no canteiro | H31: 1 | I31: × base | J31: 0.05 | K31: % | L31: Economia | N31: 150 | O31: =IF(L31="Físico",Parametros!$B$2,IF(L31="Economia",Parametros!$B$3,Parametros!$B$4)) | P31: =IF(M31="",Parametros!$B$7,M31) | Q31: =IF(AND(M31<>"",M31<10),"",ROUND(N31*O31^9,0)) | R31: =ROUND(N31*(O31^P31-1)/(O31-1),0) | S31: =IF(L31="Físico",1,Parametros!$B$6^INT(P31/Parametros!$B$5)) | T31: =IF(K31="%",H31*(1+J31*P31*S31),H31+J31*P31) | U31: A jardineira cuida de 2 canteiros ao mesmo tempo | V31: Sim (GardenCureRate)
A32: J+2 | B32: Rainha | C32: Jardineira | D32: A2 | E32: Orvalheira | F32: J0 e G0 | G32: Aceleração da gota pela jardineira | H32: 1 | I32: × base | J32: 0.1 | K32: % | L32: Físico | M32: 10 | N32: 120 | O32: =IF(L32="Físico",Parametros!$B$2,IF(L32="Economia",Parametros!$B$3,Parametros!$B$4)) | P32: =IF(M32="",Parametros!$B$7,M32) | Q32: =IF(AND(M32<>"",M32<10),"",ROUND(N32*O32^9,0)) | R32: =ROUND(N32*(O32^P32-1)/(O32-1),0) | S32: =IF(L32="Físico",1,Parametros!$B$6^INT(P32/Parametros!$B$5)) | T32: =IF(K32="%",H32*(1+J32*P32*S32),H32+J32*P32) | V32: Sim (DewTendBoost)
A33: N+1 | B33: Rainha | C33: Cuidadora | D33: A2 | E33: Ninhada atenta | F33: N1 | G33: Pausa de cuidado | H33: 1 | I33: s | J33: -0.05 | K33: % | L33: Físico | M33: 10 | N33: 120 | O33: =IF(L33="Físico",Parametros!$B$2,IF(L33="Economia",Parametros!$B$3,Parametros!$B$4)) | P33: =IF(M33="",Parametros!$B$7,M33) | Q33: =IF(AND(M33<>"",M33<10),"",ROUND(N33*O33^9,0)) | R33: =ROUND(N33*(O33^P33-1)/(O33-1),0) | S33: =IF(L33="Físico",1,Parametros!$B$6^INT(P33/Parametros!$B$5)) | T33: =IF(K33="%",H33*(1+J33*P33*S33),H33+J33*P33) | V33: Sim (CarePauseSeconds)
A34: N+2 | B34: Rainha | C34: Cuidadora | D34: A2 | E34: Turno dobrado | F34: N1 | G34: Blocos do berçário por cuidadora | H34: 2 | I34: blocos | J34: 1 | K34: abs | L34: Físico | M34: 4 | N34: 250 | O34: =IF(L34="Físico",Parametros!$B$2,IF(L34="Economia",Parametros!$B$3,Parametros!$B$4)) | P34: =IF(M34="",Parametros!$B$7,M34) | Q34: =IF(AND(M34<>"",M34<10),"",ROUND(N34*O34^9,0)) | R34: =ROUND(N34*(O34^P34-1)/(O34-1),0) | S34: =IF(L34="Físico",1,Parametros!$B$6^INT(P34/Parametros!$B$5)) | T34: =IF(K34="%",H34*(1+J34*P34*S34),H34+J34*P34) | V34: Sim (BlocksPerTender)
A35: S+1 | B35: Rainha | C35: Soldado | D35: A3 | E35: Mandíbulas afiadas | F35: S1 | G35: Dano do soldado (com S1) | H35: 4.5 | I35: dano/s | J35: 0.08 | K35: % | L35: Combate | N35: 200 | O35: =IF(L35="Físico",Parametros!$B$2,IF(L35="Economia",Parametros!$B$3,Parametros!$B$4)) | P35: =IF(M35="",Parametros!$B$7,M35) | Q35: =IF(AND(M35<>"",M35<10),"",ROUND(N35*O35^9,0)) | R35: =ROUND(N35*(O35^P35-1)/(O35-1),0) | S35: =IF(L35="Físico",1,Parametros!$B$6^INT(P35/Parametros!$B$5)) | T35: =IF(K35="%",H35*(1+J35*P35*S35),H35+J35*P35) | U35: 10% dos golpes atordoam o cupim por 0,5 s | V35: Sim (combate)
A36: S+2 | B36: Rainha | C36: Soldado | D36: A3 | E36: Carapaça grossa | F36: S2 | G36: Vida do soldado (com S2) | H36: 27 | I36: vida | J36: 0.08 | K36: % | L36: Combate | N36: 200 | O36: =IF(L36="Físico",Parametros!$B$2,IF(L36="Economia",Parametros!$B$3,Parametros!$B$4)) | P36: =IF(M36="",Parametros!$B$7,M36) | Q36: =IF(AND(M36<>"",M36<10),"",ROUND(N36*O36^9,0)) | R36: =ROUND(N36*(O36^P36-1)/(O36-1),0) | S36: =IF(L36="Físico",1,Parametros!$B$6^INT(P36/Parametros!$B$5)) | T36: =IF(K36="%",H36*(1+J36*P36*S36),H36+J36*P36) | U36: Uma vez por ataque, sobrevive ao golpe fatal com 1 de vida | V36: Sim (combate)
A37: S+3 | B37: Rainha | C37: Soldado | D37: A3 | E37: Recuperação | F37: S0 e N0 | G37: Espera para começar a curar | H37: 10 | I37: s | J37: -0.05 | K37: % | L37: Físico | M37: 10 | N37: 150 | O37: =IF(L37="Físico",Parametros!$B$2,IF(L37="Economia",Parametros!$B$3,Parametros!$B$4)) | P37: =IF(M37="",Parametros!$B$7,M37) | Q37: =IF(AND(M37<>"",M37<10),"",ROUND(N37*O37^9,0)) | R37: =ROUND(N37*(O37^P37-1)/(O37-1),0) | S37: =IF(L37="Físico",1,Parametros!$B$6^INT(P37/Parametros!$B$5)) | T37: =IF(K37="%",H37*(1+J37*P37*S37),H37+J37*P37) | V37: Sim (HealDelaySeconds)

Sheet Curva
A1: Custo (N) de cada nível
A2: Nível | B2: H+1 | C2: C+1 | D2: C+2 | E2: C+3 | F2: B+1 | G2: B+2 | H2: D+1 | I2: D+2 | J2: G+1 | K2: G+2 | L2: T+1 | M2: T+2 | N2: X+1 | O2: X+2 | P2: X+3 | Q2: M+1 | R2: M+2 | S2: Q+1 | T2: Q+2 | U2: Q+3 | V2: O+1 | W2: O+2 | X2: O+3 | Y2: L+1 | Z2: L+2 | AA2: F+1 | AB2: E+1 | AC2: E+2 | AD2: E+3 | AE2: J+1 | AF2: J+2 | AG2: N+1 | AH2: N+2 | AI2: S+1 | AJ2: S+2 | AK2: S+3
A3: 1 | B3: =IF(AND(INDEX(Galerias!$M$2:$M$37,MATCH(B$2,Galerias!$A$2:$A$37,0))<>"",$A3>INDEX(Galerias!$M$2:$M$37,MATCH(B$2,Galerias!$A$2:$A$37,0))),"",ROUND(INDEX(Galerias!$N$2:$N$37,MATCH(B$2,Galerias!$A$2:$A$37,0))*INDEX(Galerias!$O$2:$O$37,MATCH(B$2,Galerias!$A$2:$A$37,0))^($A3-1),0)) | C3: =IF(AND(INDEX(Galerias!$M$2:$M$37,MATCH(C$2,Galerias!$A$2:$A$37,0))<>"",$A3>INDEX(Galerias!$M$2:$M$37,MATCH(C$2,Galerias!$A$2:$A$37,0))),"",ROUND(INDEX(Galerias!$N$2:$N$37,MATCH(C$2,Galerias!$A$2:$A$37,0))*INDEX(Galerias!$O$2:$O$37,MATCH(C$2,Galerias!$A$2:$A$37,0))^($A3-1),0)) | D3: =IF(AND(INDEX(Galerias!$M$2:$M$37,MATCH(D$2,Galerias!$A$2:$A$37,0))<>"",$A3>INDEX(Galerias!$M$2:$M$37,MATCH(D$2,Galerias!$A$2:$A$37,0))),"",ROUND(INDEX(Galerias!$N$2:$N$37,MATCH(D$2,Galerias!$A$2:$A$37,0))*INDEX(Galerias!$O$2:$O$37,MATCH(D$2,Galerias!$A$2:$A$37,0))^($A3-1),0)) | E3: =IF(AND(INDEX(Galerias!$M$2:$M$37,MATCH(E$2,Galerias!$A$2:$A$37,0))<>"",$A3>INDEX(Galerias!$M$2:$M$37,MATCH(E$2,Galerias!$A$2:$A$37,0))),"",ROUND(INDEX(Galerias!$N$2:$N$37,MATCH(E$2,Galerias!$A$2:$A$37,0))*INDEX(Galerias!$O$2:$O$37,MATCH(E$2,Galerias!$A$2:$A$37,0))^($A3-1),0)) | F3: =IF(AND(INDEX(Galerias!$M$2:$M$37,MATCH(F$2,Galerias!$A$2:$A$37,0))<>"",$A3>INDEX(Galerias!$M$2:$M$37,MATCH(F$2,Galerias!$A$2:$A$37,0))),"",ROUND(INDEX(Galerias!$N$2:$N$37,MATCH(F$2,Galerias!$A$2:$A$37,0))*INDEX(Galerias!$O$2:$O$37,MATCH(F$2,Galerias!$A$2:$A$37,0))^($A3-1),0)) | G3: =IF(AND(INDEX(Galerias!$M$2:$M$37,MATCH(G$2,Galerias!$A$2:$A$37,0))<>"",$A3>INDEX(Galerias!$M$2:$M$37,MATCH(G$2,Galerias!$A$2:$A$37,0))),"",ROUND(INDEX(Galerias!$N$2:$N$37,MATCH(G$2,Galerias!$A$2:$A$37,0))*INDEX(Galerias!$O$2:$O$37,MATCH(G$2,Galerias!$A$2:$A$37,0))^($A3-1),0)) | H3: =IF(AND(INDEX(Galerias!$M$2:$M$37,MATCH(H$2,Galerias!$A$2:$A$37,0))<>"",$A3>INDEX(Galerias!$M$2:$M$37,MATCH(H$2,Galerias!$A$2:$A$37,0))),"",ROUND(INDEX(Galerias!$N$2:$N$37,MATCH(H$2,Galerias!$A$2:$A$37,0))*INDEX(Galerias!$O$2:$O$37,MATCH(H$2,Galerias!$A$2:$A$37,0))^($A3-1),0)) | I3: =IF(AND(INDEX(Galerias!$M$2:$M$37,MATCH(I$2,Galerias!$A$2:$A$37,0))<>"",$A3>INDEX(Galerias!$M$2:$M$37,MATCH(I$2,Galerias!$A$2:$A$37,0))),"",ROUND(INDEX(Galerias!$N$2:$N$37,MATCH(I$2,Galerias!$A$2:$A$37,0))*INDEX(Galerias!$O$2:$O$37,MATCH(I$2,Galerias!$A$2:$A$37,0))^($A3-1),0)) | ... AK3: =IF(AND(INDEX(Galerias!$M$2:$M$37,MATCH(AK$2,Galerias!$A$2:$A$37,0))<>"",$A3>INDEX(Galerias!$M$2:$M$37,MATCH(AK$2,Galerias!$A$2:$A$37,0))),"",ROUND(INDEX(Galerias!$N$2:$N$37,MATCH(AK$2,Galerias!$A$2:$A$37,0))*INDEX(Galerias!$O$2:$O$37,MATCH(AK$2,Galerias!$A$2:$A$37,0))^($A3-1),0))
A4: 2 | B4: =IF(AND(INDEX(Galerias!$M$2:$M$37,MATCH(B$2,Galerias!$A$2:$A$37,0))<>"",$A4>INDEX(Galerias!$M$2:$M$37,MATCH(B$2,Galerias!$A$2:$A$37,0))),"",ROUND(INDEX(Galerias!$N$2:$N$37,MATCH(B$2,Galerias!$A$2:$A$37,0))*INDEX(Galerias!$O$2:$O$37,MATCH(B$2,Galerias!$A$2:$A$37,0))^($A4-1),0)) | C4: =IF(AND(INDEX(Galerias!$M$2:$M$37,MATCH(C$2,Galerias!$A$2:$A$37,0))<>"",$A4>INDEX(Galerias!$M$2:$M$37,MATCH(C$2,Galerias!$A$2:$A$37,0))),"",ROUND(INDEX(Galerias!$N$2:$N$37,MATCH(C$2,Galerias!$A$2:$A$37,0))*INDEX(Galerias!$O$2:$O$37,MATCH(C$2,Galerias!$A$2:$A$37,0))^($A4-1),0)) | D4: =IF(AND(INDEX(Galerias!$M$2:$M$37,MATCH(D$2,Galerias!$A$2:$A$37,0))<>"",$A4>INDEX(Galerias!$M$2:$M$37,MATCH(D$2,Galerias!$A$2:$A$37,0))),"",ROUND(INDEX(Galerias!$N$2:$N$37,MATCH(D$2,Galerias!$A$2:$A$37,0))*INDEX(Galerias!$O$2:$O$37,MATCH(D$2,Galerias!$A$2:$A$37,0))^($A4-1),0)) | E4: =IF(AND(INDEX(Galerias!$M$2:$M$37,MATCH(E$2,Galerias!$A$2:$A$37,0))<>"",$A4>INDEX(Galerias!$M$2:$M$37,MATCH(E$2,Galerias!$A$2:$A$37,0))),"",ROUND(INDEX(Galerias!$N$2:$N$37,MATCH(E$2,Galerias!$A$2:$A$37,0))*INDEX(Galerias!$O$2:$O$37,MATCH(E$2,Galerias!$A$2:$A$37,0))^($A4-1),0)) | F4: =IF(AND(INDEX(Galerias!$M$2:$M$37,MATCH(F$2,Galerias!$A$2:$A$37,0))<>"",$A4>INDEX(Galerias!$M$2:$M$37,MATCH(F$2,Galerias!$A$2:$A$37,0))),"",ROUND(INDEX(Galerias!$N$2:$N$37,MATCH(F$2,Galerias!$A$2:$A$37,0))*INDEX(Galerias!$O$2:$O$37,MATCH(F$2,Galerias!$A$2:$A$37,0))^($A4-1),0)) | G4: =IF(AND(INDEX(Galerias!$M$2:$M$37,MATCH(G$2,Galerias!$A$2:$A$37,0))<>"",$A4>INDEX(Galerias!$M$2:$M$37,MATCH(G$2,Galerias!$A$2:$A$37,0))),"",ROUND(INDEX(Galerias!$N$2:$N$37,MATCH(G$2,Galerias!$A$2:$A$37,0))*INDEX(Galerias!$O$2:$O$37,MATCH(G$2,Galerias!$A$2:$A$37,0))^($A4-1),0)) | H4: =IF(AND(INDEX(Galerias!$M$2:$M$37,MATCH(H$2,Galerias!$A$2:$A$37,0))<>"",$A4>INDEX(Galerias!$M$2:$M$37,MATCH(H$2,Galerias!$A$2:$A$37,0))),"",ROUND(INDEX(Galerias!$N$2:$N$37,MATCH(H$2,Galerias!$A$2:$A$37,0))*INDEX(Galerias!$O$2:$O$37,MATCH(H$2,Galerias!$A$2:$A$37,0))^($A4-1),0)) | I4: =IF(AND(INDEX(Galerias!$M$2:$M$37,MATCH(I$2,Galerias!$A$2:$A$37,0))<>"",$A4>INDEX(Galerias!$M$2:$M$37,MATCH(I$2,Galerias!$A$2:$A$37,0))),"",ROUND(INDEX(Galerias!$N$2:$N$37,MATCH(I$2,Galerias!$A$2:$A$37,0))*INDEX(Galerias!$O$2:$O$37,MATCH(I$2,Galerias!$A$2:$A$37,0))^($A4-1),0)) | ... AK4: =IF(AND(INDEX(Galerias!$M$2:$M$37,MATCH(AK$2,Galerias!$A$2:$A$37,0))<>"",$A4>INDEX(Galerias!$M$2:$M$37,MATCH(AK$2,Galerias!$A$2:$A$37,0))),"",ROUND(INDEX(Galerias!$N$2:$N$37,MATCH(AK$2,Galerias!$A$2:$A$37,0))*INDEX(Galerias!$O$2:$O$37,MATCH(AK$2,Galerias!$A$2:$A$37,0))^($A4-1),0))
A5: 3 | B5: =IF(AND(INDEX(Galerias!$M$2:$M$37,MATCH(B$2,Galerias!$A$2:$A$37,0))<>"",$A5>INDEX(Galerias!$M$2:$M$37,MATCH(B$2,Galerias!$A$2:$A$37,0))),"",ROUND(INDEX(Galerias!$N$2:$N$37,MATCH(B$2,Galerias!$A$2:$A$37,0))*INDEX(Galerias!$O$2:$O$37,MATCH(B$2,Galerias!$A$2:$A$37,0))^($A5-1),0)) | C5: =IF(AND(INDEX(Galerias!$M$2:$M$37,MATCH(C$2,Galerias!$A$2:$A$37,0))<>"",$A5>INDEX(Galerias!$M$2:$M$37,MATCH(C$2,Galerias!$A$2:$A$37,0))),"",ROUND(INDEX(Galerias!$N$2:$N$37,MATCH(C$2,Galerias!$A$2:$A$37,0))*INDEX(Galerias!$O$2:$O$37,MATCH(C$2,Galerias!$A$2:$A$37,0))^($A5-1),0)) | D5: =IF(AND(INDEX(Galerias!$M$2:$M$37,MATCH(D$2,Galerias!$A$2:$A$37,0))<>"",$A5>INDEX(Galerias!$M$2:$M$37,MATCH(D$2,Galerias!$A$2:$A$37,0))),"",ROUND(INDEX(Galerias!$N$2:$N$37,MATCH(D$2,Galerias!$A$2:$A$37,0))*INDEX(Galerias!$O$2:$O$37,MATCH(D$2,Galerias!$A$2:$A$37,0))^($A5-1),0)) | E5: =IF(AND(INDEX(Galerias!$M$2:$M$37,MATCH(E$2,Galerias!$A$2:$A$37,0))<>"",$A5>INDEX(Galerias!$M$2:$M$37,MATCH(E$2,Galerias!$A$2:$A$37,0))),"",ROUND(INDEX(Galerias!$N$2:$N$37,MATCH(E$2,Galerias!$A$2:$A$37,0))*INDEX(Galerias!$O$2:$O$37,MATCH(E$2,Galerias!$A$2:$A$37,0))^($A5-1),0)) | F5: =IF(AND(INDEX(Galerias!$M$2:$M$37,MATCH(F$2,Galerias!$A$2:$A$37,0))<>"",$A5>INDEX(Galerias!$M$2:$M$37,MATCH(F$2,Galerias!$A$2:$A$37,0))),"",ROUND(INDEX(Galerias!$N$2:$N$37,MATCH(F$2,Galerias!$A$2:$A$37,0))*INDEX(Galerias!$O$2:$O$37,MATCH(F$2,Galerias!$A$2:$A$37,0))^($A5-1),0)) | G5: =IF(AND(INDEX(Galerias!$M$2:$M$37,MATCH(G$2,Galerias!$A$2:$A$37,0))<>"",$A5>INDEX(Galerias!$M$2:$M$37,MATCH(G$2,Galerias!$A$2:$A$37,0))),"",ROUND(INDEX(Galerias!$N$2:$N$37,MATCH(G$2,Galerias!$A$2:$A$37,0))*INDEX(Galerias!$O$2:$O$37,MATCH(G$2,Galerias!$A$2:$A$37,0))^($A5-1),0)) | H5: =IF(AND(INDEX(Galerias!$M$2:$M$37,MATCH(H$2,Galerias!$A$2:$A$37,0))<>"",$A5>INDEX(Galerias!$M$2:$M$37,MATCH(H$2,Galerias!$A$2:$A$37,0))),"",ROUND(INDEX(Galerias!$N$2:$N$37,MATCH(H$2,Galerias!$A$2:$A$37,0))*INDEX(Galerias!$O$2:$O$37,MATCH(H$2,Galerias!$A$2:$A$37,0))^($A5-1),0)) | I5: =IF(AND(INDEX(Galerias!$M$2:$M$37,MATCH(I$2,Galerias!$A$2:$A$37,0))<>"",$A5>INDEX(Galerias!$M$2:$M$37,MATCH(I$2,Galerias!$A$2:$A$37,0))),"",ROUND(INDEX(Galerias!$N$2:$N$37,MATCH(I$2,Galerias!$A$2:$A$37,0))*INDEX(Galerias!$O$2:$O$37,MATCH(I$2,Galerias!$A$2:$A$37,0))^($A5-1),0)) | ... AK5: =IF(AND(INDEX(Galerias!$M$2:$M$37,MATCH(AK$2,Galerias!$A$2:$A$37,0))<>"",$A5>INDEX(Galerias!$M$2:$M$37,MATCH(AK$2,Galerias!$A$2:$A$37,0))),"",ROUND(INDEX(Galerias!$N$2:$N$37,MATCH(AK$2,Galerias!$A$2:$A$37,0))*INDEX(Galerias!$O$2:$O$37,MATCH(AK$2,Galerias!$A$2:$A$37,0))^($A5-1),0))
A6: 4 | B6: =IF(AND(INDEX(Galerias!$M$2:$M$37,MATCH(B$2,Galerias!$A$2:$A$37,0))<>"",$A6>INDEX(Galerias!$M$2:$M$37,MATCH(B$2,Galerias!$A$2:$A$37,0))),"",ROUND(INDEX(Galerias!$N$2:$N$37,MATCH(B$2,Galerias!$A$2:$A$37,0))*INDEX(Galerias!$O$2:$O$37,MATCH(B$2,Galerias!$A$2:$A$37,0))^($A6-1),0)) | C6: =IF(AND(INDEX(Galerias!$M$2:$M$37,MATCH(C$2,Galerias!$A$2:$A$37,0))<>"",$A6>INDEX(Galerias!$M$2:$M$37,MATCH(C$2,Galerias!$A$2:$A$37,0))),"",ROUND(INDEX(Galerias!$N$2:$N$37,MATCH(C$2,Galerias!$A$2:$A$37,0))*INDEX(Galerias!$O$2:$O$37,MATCH(C$2,Galerias!$A$2:$A$37,0))^($A6-1),0)) | D6: =IF(AND(INDEX(Galerias!$M$2:$M$37,MATCH(D$2,Galerias!$A$2:$A$37,0))<>"",$A6>INDEX(Galerias!$M$2:$M$37,MATCH(D$2,Galerias!$A$2:$A$37,0))),"",ROUND(INDEX(Galerias!$N$2:$N$37,MATCH(D$2,Galerias!$A$2:$A$37,0))*INDEX(Galerias!$O$2:$O$37,MATCH(D$2,Galerias!$A$2:$A$37,0))^($A6-1),0)) | E6: =IF(AND(INDEX(Galerias!$M$2:$M$37,MATCH(E$2,Galerias!$A$2:$A$37,0))<>"",$A6>INDEX(Galerias!$M$2:$M$37,MATCH(E$2,Galerias!$A$2:$A$37,0))),"",ROUND(INDEX(Galerias!$N$2:$N$37,MATCH(E$2,Galerias!$A$2:$A$37,0))*INDEX(Galerias!$O$2:$O$37,MATCH(E$2,Galerias!$A$2:$A$37,0))^($A6-1),0)) | F6: =IF(AND(INDEX(Galerias!$M$2:$M$37,MATCH(F$2,Galerias!$A$2:$A$37,0))<>"",$A6>INDEX(Galerias!$M$2:$M$37,MATCH(F$2,Galerias!$A$2:$A$37,0))),"",ROUND(INDEX(Galerias!$N$2:$N$37,MATCH(F$2,Galerias!$A$2:$A$37,0))*INDEX(Galerias!$O$2:$O$37,MATCH(F$2,Galerias!$A$2:$A$37,0))^($A6-1),0)) | G6: =IF(AND(INDEX(Galerias!$M$2:$M$37,MATCH(G$2,Galerias!$A$2:$A$37,0))<>"",$A6>INDEX(Galerias!$M$2:$M$37,MATCH(G$2,Galerias!$A$2:$A$37,0))),"",ROUND(INDEX(Galerias!$N$2:$N$37,MATCH(G$2,Galerias!$A$2:$A$37,0))*INDEX(Galerias!$O$2:$O$37,MATCH(G$2,Galerias!$A$2:$A$37,0))^($A6-1),0)) | H6: =IF(AND(INDEX(Galerias!$M$2:$M$37,MATCH(H$2,Galerias!$A$2:$A$37,0))<>"",$A6>INDEX(Galerias!$M$2:$M$37,MATCH(H$2,Galerias!$A$2:$A$37,0))),"",ROUND(INDEX(Galerias!$N$2:$N$37,MATCH(H$2,Galerias!$A$2:$A$37,0))*INDEX(Galerias!$O$2:$O$37,MATCH(H$2,Galerias!$A$2:$A$37,0))^($A6-1),0)) | I6: =IF(AND(INDEX(Galerias!$M$2:$M$37,MATCH(I$2,Galerias!$A$2:$A$37,0))<>"",$A6>INDEX(Galerias!$M$2:$M$37,MATCH(I$2,Galerias!$A$2:$A$37,0))),"",ROUND(INDEX(Galerias!$N$2:$N$37,MATCH(I$2,Galerias!$A$2:$A$37,0))*INDEX(Galerias!$O$2:$O$37,MATCH(I$2,Galerias!$A$2:$A$37,0))^($A6-1),0)) | ... AK6: =IF(AND(INDEX(Galerias!$M$2:$M$37,MATCH(AK$2,Galerias!$A$2:$A$37,0))<>"",$A6>INDEX(Galerias!$M$2:$M$37,MATCH(AK$2,Galerias!$A$2:$A$37,0))),"",ROUND(INDEX(Galerias!$N$2:$N$37,MATCH(AK$2,Galerias!$A$2:$A$37,0))*INDEX(Galerias!$O$2:$O$37,MATCH(AK$2,Galerias!$A$2:$A$37,0))^($A6-1),0))
A7: 5 | B7: =IF(AND(INDEX(Galerias!$M$2:$M$37,MATCH(B$2,Galerias!$A$2:$A$37,0))<>"",$A7>INDEX(Galerias!$M$2:$M$37,MATCH(B$2,Galerias!$A$2:$A$37,0))),"",ROUND(INDEX(Galerias!$N$2:$N$37,MATCH(B$2,Galerias!$A$2:$A$37,0))*INDEX(Galerias!$O$2:$O$37,MATCH(B$2,Galerias!$A$2:$A$37,0))^($A7-1),0)) | C7: =IF(AND(INDEX(Galerias!$M$2:$M$37,MATCH(C$2,Galerias!$A$2:$A$37,0))<>"",$A7>INDEX(Galerias!$M$2:$M$37,MATCH(C$2,Galerias!$A$2:$A$37,0))),"",ROUND(INDEX(Galerias!$N$2:$N$37,MATCH(C$2,Galerias!$A$2:$A$37,0))*INDEX(Galerias!$O$2:$O$37,MATCH(C$2,Galerias!$A$2:$A$37,0))^($A7-1),0)) | D7: =IF(AND(INDEX(Galerias!$M$2:$M$37,MATCH(D$2,Galerias!$A$2:$A$37,0))<>"",$A7>INDEX(Galerias!$M$2:$M$37,MATCH(D$2,Galerias!$A$2:$A$37,0))),"",ROUND(INDEX(Galerias!$N$2:$N$37,MATCH(D$2,Galerias!$A$2:$A$37,0))*INDEX(Galerias!$O$2:$O$37,MATCH(D$2,Galerias!$A$2:$A$37,0))^($A7-1),0)) | E7: =IF(AND(INDEX(Galerias!$M$2:$M$37,MATCH(E$2,Galerias!$A$2:$A$37,0))<>"",$A7>INDEX(Galerias!$M$2:$M$37,MATCH(E$2,Galerias!$A$2:$A$37,0))),"",ROUND(INDEX(Galerias!$N$2:$N$37,MATCH(E$2,Galerias!$A$2:$A$37,0))*INDEX(Galerias!$O$2:$O$37,MATCH(E$2,Galerias!$A$2:$A$37,0))^($A7-1),0)) | F7: =IF(AND(INDEX(Galerias!$M$2:$M$37,MATCH(F$2,Galerias!$A$2:$A$37,0))<>"",$A7>INDEX(Galerias!$M$2:$M$37,MATCH(F$2,Galerias!$A$2:$A$37,0))),"",ROUND(INDEX(Galerias!$N$2:$N$37,MATCH(F$2,Galerias!$A$2:$A$37,0))*INDEX(Galerias!$O$2:$O$37,MATCH(F$2,Galerias!$A$2:$A$37,0))^($A7-1),0)) | G7: =IF(AND(INDEX(Galerias!$M$2:$M$37,MATCH(G$2,Galerias!$A$2:$A$37,0))<>"",$A7>INDEX(Galerias!$M$2:$M$37,MATCH(G$2,Galerias!$A$2:$A$37,0))),"",ROUND(INDEX(Galerias!$N$2:$N$37,MATCH(G$2,Galerias!$A$2:$A$37,0))*INDEX(Galerias!$O$2:$O$37,MATCH(G$2,Galerias!$A$2:$A$37,0))^($A7-1),0)) | H7: =IF(AND(INDEX(Galerias!$M$2:$M$37,MATCH(H$2,Galerias!$A$2:$A$37,0))<>"",$A7>INDEX(Galerias!$M$2:$M$37,MATCH(H$2,Galerias!$A$2:$A$37,0))),"",ROUND(INDEX(Galerias!$N$2:$N$37,MATCH(H$2,Galerias!$A$2:$A$37,0))*INDEX(Galerias!$O$2:$O$37,MATCH(H$2,Galerias!$A$2:$A$37,0))^($A7-1),0)) | I7: =IF(AND(INDEX(Galerias!$M$2:$M$37,MATCH(I$2,Galerias!$A$2:$A$37,0))<>"",$A7>INDEX(Galerias!$M$2:$M$37,MATCH(I$2,Galerias!$A$2:$A$37,0))),"",ROUND(INDEX(Galerias!$N$2:$N$37,MATCH(I$2,Galerias!$A$2:$A$37,0))*INDEX(Galerias!$O$2:$O$37,MATCH(I$2,Galerias!$A$2:$A$37,0))^($A7-1),0)) | ... AK7: =IF(AND(INDEX(Galerias!$M$2:$M$37,MATCH(AK$2,Galerias!$A$2:$A$37,0))<>"",$A7>INDEX(Galerias!$M$2:$M$37,MATCH(AK$2,Galerias!$A$2:$A$37,0))),"",ROUND(INDEX(Galerias!$N$2:$N$37,MATCH(AK$2,Galerias!$A$2:$A$37,0))*INDEX(Galerias!$O$2:$O$37,MATCH(AK$2,Galerias!$A$2:$A$37,0))^($A7-1),0))
A8: 6 | B8: =IF(AND(INDEX(Galerias!$M$2:$M$37,MATCH(B$2,Galerias!$A$2:$A$37,0))<>"",$A8>INDEX(Galerias!$M$2:$M$37,MATCH(B$2,Galerias!$A$2:$A$37,0))),"",ROUND(INDEX(Galerias!$N$2:$N$37,MATCH(B$2,Galerias!$A$2:$A$37,0))*INDEX(Galerias!$O$2:$O$37,MATCH(B$2,Galerias!$A$2:$A$37,0))^($A8-1),0)) | C8: =IF(AND(INDEX(Galerias!$M$2:$M$37,MATCH(C$2,Galerias!$A$2:$A$37,0))<>"",$A8>INDEX(Galerias!$M$2:$M$37,MATCH(C$2,Galerias!$A$2:$A$37,0))),"",ROUND(INDEX(Galerias!$N$2:$N$37,MATCH(C$2,Galerias!$A$2:$A$37,0))*INDEX(Galerias!$O$2:$O$37,MATCH(C$2,Galerias!$A$2:$A$37,0))^($A8-1),0)) | D8: =IF(AND(INDEX(Galerias!$M$2:$M$37,MATCH(D$2,Galerias!$A$2:$A$37,0))<>"",$A8>INDEX(Galerias!$M$2:$M$37,MATCH(D$2,Galerias!$A$2:$A$37,0))),"",ROUND(INDEX(Galerias!$N$2:$N$37,MATCH(D$2,Galerias!$A$2:$A$37,0))*INDEX(Galerias!$O$2:$O$37,MATCH(D$2,Galerias!$A$2:$A$37,0))^($A8-1),0)) | E8: =IF(AND(INDEX(Galerias!$M$2:$M$37,MATCH(E$2,Galerias!$A$2:$A$37,0))<>"",$A8>INDEX(Galerias!$M$2:$M$37,MATCH(E$2,Galerias!$A$2:$A$37,0))),"",ROUND(INDEX(Galerias!$N$2:$N$37,MATCH(E$2,Galerias!$A$2:$A$37,0))*INDEX(Galerias!$O$2:$O$37,MATCH(E$2,Galerias!$A$2:$A$37,0))^($A8-1),0)) | F8: =IF(AND(INDEX(Galerias!$M$2:$M$37,MATCH(F$2,Galerias!$A$2:$A$37,0))<>"",$A8>INDEX(Galerias!$M$2:$M$37,MATCH(F$2,Galerias!$A$2:$A$37,0))),"",ROUND(INDEX(Galerias!$N$2:$N$37,MATCH(F$2,Galerias!$A$2:$A$37,0))*INDEX(Galerias!$O$2:$O$37,MATCH(F$2,Galerias!$A$2:$A$37,0))^($A8-1),0)) | G8: =IF(AND(INDEX(Galerias!$M$2:$M$37,MATCH(G$2,Galerias!$A$2:$A$37,0))<>"",$A8>INDEX(Galerias!$M$2:$M$37,MATCH(G$2,Galerias!$A$2:$A$37,0))),"",ROUND(INDEX(Galerias!$N$2:$N$37,MATCH(G$2,Galerias!$A$2:$A$37,0))*INDEX(Galerias!$O$2:$O$37,MATCH(G$2,Galerias!$A$2:$A$37,0))^($A8-1),0)) | H8: =IF(AND(INDEX(Galerias!$M$2:$M$37,MATCH(H$2,Galerias!$A$2:$A$37,0))<>"",$A8>INDEX(Galerias!$M$2:$M$37,MATCH(H$2,Galerias!$A$2:$A$37,0))),"",ROUND(INDEX(Galerias!$N$2:$N$37,MATCH(H$2,Galerias!$A$2:$A$37,0))*INDEX(Galerias!$O$2:$O$37,MATCH(H$2,Galerias!$A$2:$A$37,0))^($A8-1),0)) | I8: =IF(AND(INDEX(Galerias!$M$2:$M$37,MATCH(I$2,Galerias!$A$2:$A$37,0))<>"",$A8>INDEX(Galerias!$M$2:$M$37,MATCH(I$2,Galerias!$A$2:$A$37,0))),"",ROUND(INDEX(Galerias!$N$2:$N$37,MATCH(I$2,Galerias!$A$2:$A$37,0))*INDEX(Galerias!$O$2:$O$37,MATCH(I$2,Galerias!$A$2:$A$37,0))^($A8-1),0)) | ... AK8: =IF(AND(INDEX(Galerias!$M$2:$M$37,MATCH(AK$2,Galerias!$A$2:$A$37,0))<>"",$A8>INDEX(Galerias!$M$2:$M$37,MATCH(AK$2,Galerias!$A$2:$A$37,0))),"",ROUND(INDEX(Galerias!$N$2:$N$37,MATCH(AK$2,Galerias!$A$2:$A$37,0))*INDEX(Galerias!$O$2:$O$37,MATCH(AK$2,Galerias!$A$2:$A$37,0))^($A8-1),0))
A9: 7 | B9: =IF(AND(INDEX(Galerias!$M$2:$M$37,MATCH(B$2,Galerias!$A$2:$A$37,0))<>"",$A9>INDEX(Galerias!$M$2:$M$37,MATCH(B$2,Galerias!$A$2:$A$37,0))),"",ROUND(INDEX(Galerias!$N$2:$N$37,MATCH(B$2,Galerias!$A$2:$A$37,0))*INDEX(Galerias!$O$2:$O$37,MATCH(B$2,Galerias!$A$2:$A$37,0))^($A9-1),0)) | C9: =IF(AND(INDEX(Galerias!$M$2:$M$37,MATCH(C$2,Galerias!$A$2:$A$37,0))<>"",$A9>INDEX(Galerias!$M$2:$M$37,MATCH(C$2,Galerias!$A$2:$A$37,0))),"",ROUND(INDEX(Galerias!$N$2:$N$37,MATCH(C$2,Galerias!$A$2:$A$37,0))*INDEX(Galerias!$O$2:$O$37,MATCH(C$2,Galerias!$A$2:$A$37,0))^($A9-1),0)) | D9: =IF(AND(INDEX(Galerias!$M$2:$M$37,MATCH(D$2,Galerias!$A$2:$A$37,0))<>"",$A9>INDEX(Galerias!$M$2:$M$37,MATCH(D$2,Galerias!$A$2:$A$37,0))),"",ROUND(INDEX(Galerias!$N$2:$N$37,MATCH(D$2,Galerias!$A$2:$A$37,0))*INDEX(Galerias!$O$2:$O$37,MATCH(D$2,Galerias!$A$2:$A$37,0))^($A9-1),0)) | E9: =IF(AND(INDEX(Galerias!$M$2:$M$37,MATCH(E$2,Galerias!$A$2:$A$37,0))<>"",$A9>INDEX(Galerias!$M$2:$M$37,MATCH(E$2,Galerias!$A$2:$A$37,0))),"",ROUND(INDEX(Galerias!$N$2:$N$37,MATCH(E$2,Galerias!$A$2:$A$37,0))*INDEX(Galerias!$O$2:$O$37,MATCH(E$2,Galerias!$A$2:$A$37,0))^($A9-1),0)) | F9: =IF(AND(INDEX(Galerias!$M$2:$M$37,MATCH(F$2,Galerias!$A$2:$A$37,0))<>"",$A9>INDEX(Galerias!$M$2:$M$37,MATCH(F$2,Galerias!$A$2:$A$37,0))),"",ROUND(INDEX(Galerias!$N$2:$N$37,MATCH(F$2,Galerias!$A$2:$A$37,0))*INDEX(Galerias!$O$2:$O$37,MATCH(F$2,Galerias!$A$2:$A$37,0))^($A9-1),0)) | G9: =IF(AND(INDEX(Galerias!$M$2:$M$37,MATCH(G$2,Galerias!$A$2:$A$37,0))<>"",$A9>INDEX(Galerias!$M$2:$M$37,MATCH(G$2,Galerias!$A$2:$A$37,0))),"",ROUND(INDEX(Galerias!$N$2:$N$37,MATCH(G$2,Galerias!$A$2:$A$37,0))*INDEX(Galerias!$O$2:$O$37,MATCH(G$2,Galerias!$A$2:$A$37,0))^($A9-1),0)) | H9: =IF(AND(INDEX(Galerias!$M$2:$M$37,MATCH(H$2,Galerias!$A$2:$A$37,0))<>"",$A9>INDEX(Galerias!$M$2:$M$37,MATCH(H$2,Galerias!$A$2:$A$37,0))),"",ROUND(INDEX(Galerias!$N$2:$N$37,MATCH(H$2,Galerias!$A$2:$A$37,0))*INDEX(Galerias!$O$2:$O$37,MATCH(H$2,Galerias!$A$2:$A$37,0))^($A9-1),0)) | I9: =IF(AND(INDEX(Galerias!$M$2:$M$37,MATCH(I$2,Galerias!$A$2:$A$37,0))<>"",$A9>INDEX(Galerias!$M$2:$M$37,MATCH(I$2,Galerias!$A$2:$A$37,0))),"",ROUND(INDEX(Galerias!$N$2:$N$37,MATCH(I$2,Galerias!$A$2:$A$37,0))*INDEX(Galerias!$O$2:$O$37,MATCH(I$2,Galerias!$A$2:$A$37,0))^($A9-1),0)) | ... AK9: =IF(AND(INDEX(Galerias!$M$2:$M$37,MATCH(AK$2,Galerias!$A$2:$A$37,0))<>"",$A9>INDEX(Galerias!$M$2:$M$37,MATCH(AK$2,Galerias!$A$2:$A$37,0))),"",ROUND(INDEX(Galerias!$N$2:$N$37,MATCH(AK$2,Galerias!$A$2:$A$37,0))*INDEX(Galerias!$O$2:$O$37,MATCH(AK$2,Galerias!$A$2:$A$37,0))^($A9-1),0))
A10: 8 | B10: =IF(AND(INDEX(Galerias!$M$2:$M$37,MATCH(B$2,Galerias!$A$2:$A$37,0))<>"",$A10>INDEX(Galerias!$M$2:$M$37,MATCH(B$2,Galerias!$A$2:$A$37,0))),"",ROUND(INDEX(Galerias!$N$2:$N$37,MATCH(B$2,Galerias!$A$2:$A$37,0))*INDEX(Galerias!$O$2:$O$37,MATCH(B$2,Galerias!$A$2:$A$37,0))^($A10-1),0)) | C10: =IF(AND(INDEX(Galerias!$M$2:$M$37,MATCH(C$2,Galerias!$A$2:$A$37,0))<>"",$A10>INDEX(Galerias!$M$2:$M$37,MATCH(C$2,Galerias!$A$2:$A$37,0))),"",ROUND(INDEX(Galerias!$N$2:$N$37,MATCH(C$2,Galerias!$A$2:$A$37,0))*INDEX(Galerias!$O$2:$O$37,MATCH(C$2,Galerias!$A$2:$A$37,0))^($A10-1),0)) | D10: =IF(AND(INDEX(Galerias!$M$2:$M$37,MATCH(D$2,Galerias!$A$2:$A$37,0))<>"",$A10>INDEX(Galerias!$M$2:$M$37,MATCH(D$2,Galerias!$A$2:$A$37,0))),"",ROUND(INDEX(Galerias!$N$2:$N$37,MATCH(D$2,Galerias!$A$2:$A$37,0))*INDEX(Galerias!$O$2:$O$37,MATCH(D$2,Galerias!$A$2:$A$37,0))^($A10-1),0)) | E10: =IF(AND(INDEX(Galerias!$M$2:$M$37,MATCH(E$2,Galerias!$A$2:$A$37,0))<>"",$A10>INDEX(Galerias!$M$2:$M$37,MATCH(E$2,Galerias!$A$2:$A$37,0))),"",ROUND(INDEX(Galerias!$N$2:$N$37,MATCH(E$2,Galerias!$A$2:$A$37,0))*INDEX(Galerias!$O$2:$O$37,MATCH(E$2,Galerias!$A$2:$A$37,0))^($A10-1),0)) | F10: =IF(AND(INDEX(Galerias!$M$2:$M$37,MATCH(F$2,Galerias!$A$2:$A$37,0))<>"",$A10>INDEX(Galerias!$M$2:$M$37,MATCH(F$2,Galerias!$A$2:$A$37,0))),"",ROUND(INDEX(Galerias!$N$2:$N$37,MATCH(F$2,Galerias!$A$2:$A$37,0))*INDEX(Galerias!$O$2:$O$37,MATCH(F$2,Galerias!$A$2:$A$37,0))^($A10-1),0)) | G10: =IF(AND(INDEX(Galerias!$M$2:$M$37,MATCH(G$2,Galerias!$A$2:$A$37,0))<>"",$A10>INDEX(Galerias!$M$2:$M$37,MATCH(G$2,Galerias!$A$2:$A$37,0))),"",ROUND(INDEX(Galerias!$N$2:$N$37,MATCH(G$2,Galerias!$A$2:$A$37,0))*INDEX(Galerias!$O$2:$O$37,MATCH(G$2,Galerias!$A$2:$A$37,0))^($A10-1),0)) | H10: =IF(AND(INDEX(Galerias!$M$2:$M$37,MATCH(H$2,Galerias!$A$2:$A$37,0))<>"",$A10>INDEX(Galerias!$M$2:$M$37,MATCH(H$2,Galerias!$A$2:$A$37,0))),"",ROUND(INDEX(Galerias!$N$2:$N$37,MATCH(H$2,Galerias!$A$2:$A$37,0))*INDEX(Galerias!$O$2:$O$37,MATCH(H$2,Galerias!$A$2:$A$37,0))^($A10-1),0)) | I10: =IF(AND(INDEX(Galerias!$M$2:$M$37,MATCH(I$2,Galerias!$A$2:$A$37,0))<>"",$A10>INDEX(Galerias!$M$2:$M$37,MATCH(I$2,Galerias!$A$2:$A$37,0))),"",ROUND(INDEX(Galerias!$N$2:$N$37,MATCH(I$2,Galerias!$A$2:$A$37,0))*INDEX(Galerias!$O$2:$O$37,MATCH(I$2,Galerias!$A$2:$A$37,0))^($A10-1),0)) | ... AK10: =IF(AND(INDEX(Galerias!$M$2:$M$37,MATCH(AK$2,Galerias!$A$2:$A$37,0))<>"",$A10>INDEX(Galerias!$M$2:$M$37,MATCH(AK$2,Galerias!$A$2:$A$37,0))),"",ROUND(INDEX(Galerias!$N$2:$N$37,MATCH(AK$2,Galerias!$A$2:$A$37,0))*INDEX(Galerias!$O$2:$O$37,MATCH(AK$2,Galerias!$A$2:$A$37,0))^($A10-1),0))
A11: 9 | B11: =IF(AND(INDEX(Galerias!$M$2:$M$37,MATCH(B$2,Galerias!$A$2:$A$37,0))<>"",$A11>INDEX(Galerias!$M$2:$M$37,MATCH(B$2,Galerias!$A$2:$A$37,0))),"",ROUND(INDEX(Galerias!$N$2:$N$37,MATCH(B$2,Galerias!$A$2:$A$37,0))*INDEX(Galerias!$O$2:$O$37,MATCH(B$2,Galerias!$A$2:$A$37,0))^($A11-1),0)) | C11: =IF(AND(INDEX(Galerias!$M$2:$M$37,MATCH(C$2,Galerias!$A$2:$A$37,0))<>"",$A11>INDEX(Galerias!$M$2:$M$37,MATCH(C$2,Galerias!$A$2:$A$37,0))),"",ROUND(INDEX(Galerias!$N$2:$N$37,MATCH(C$2,Galerias!$A$2:$A$37,0))*INDEX(Galerias!$O$2:$O$37,MATCH(C$2,Galerias!$A$2:$A$37,0))^($A11-1),0)) | D11: =IF(AND(INDEX(Galerias!$M$2:$M$37,MATCH(D$2,Galerias!$A$2:$A$37,0))<>"",$A11>INDEX(Galerias!$M$2:$M$37,MATCH(D$2,Galerias!$A$2:$A$37,0))),"",ROUND(INDEX(Galerias!$N$2:$N$37,MATCH(D$2,Galerias!$A$2:$A$37,0))*INDEX(Galerias!$O$2:$O$37,MATCH(D$2,Galerias!$A$2:$A$37,0))^($A11-1),0)) | E11: =IF(AND(INDEX(Galerias!$M$2:$M$37,MATCH(E$2,Galerias!$A$2:$A$37,0))<>"",$A11>INDEX(Galerias!$M$2:$M$37,MATCH(E$2,Galerias!$A$2:$A$37,0))),"",ROUND(INDEX(Galerias!$N$2:$N$37,MATCH(E$2,Galerias!$A$2:$A$37,0))*INDEX(Galerias!$O$2:$O$37,MATCH(E$2,Galerias!$A$2:$A$37,0))^($A11-1),0)) | F11: =IF(AND(INDEX(Galerias!$M$2:$M$37,MATCH(F$2,Galerias!$A$2:$A$37,0))<>"",$A11>INDEX(Galerias!$M$2:$M$37,MATCH(F$2,Galerias!$A$2:$A$37,0))),"",ROUND(INDEX(Galerias!$N$2:$N$37,MATCH(F$2,Galerias!$A$2:$A$37,0))*INDEX(Galerias!$O$2:$O$37,MATCH(F$2,Galerias!$A$2:$A$37,0))^($A11-1),0)) | G11: =IF(AND(INDEX(Galerias!$M$2:$M$37,MATCH(G$2,Galerias!$A$2:$A$37,0))<>"",$A11>INDEX(Galerias!$M$2:$M$37,MATCH(G$2,Galerias!$A$2:$A$37,0))),"",ROUND(INDEX(Galerias!$N$2:$N$37,MATCH(G$2,Galerias!$A$2:$A$37,0))*INDEX(Galerias!$O$2:$O$37,MATCH(G$2,Galerias!$A$2:$A$37,0))^($A11-1),0)) | H11: =IF(AND(INDEX(Galerias!$M$2:$M$37,MATCH(H$2,Galerias!$A$2:$A$37,0))<>"",$A11>INDEX(Galerias!$M$2:$M$37,MATCH(H$2,Galerias!$A$2:$A$37,0))),"",ROUND(INDEX(Galerias!$N$2:$N$37,MATCH(H$2,Galerias!$A$2:$A$37,0))*INDEX(Galerias!$O$2:$O$37,MATCH(H$2,Galerias!$A$2:$A$37,0))^($A11-1),0)) | I11: =IF(AND(INDEX(Galerias!$M$2:$M$37,MATCH(I$2,Galerias!$A$2:$A$37,0))<>"",$A11>INDEX(Galerias!$M$2:$M$37,MATCH(I$2,Galerias!$A$2:$A$37,0))),"",ROUND(INDEX(Galerias!$N$2:$N$37,MATCH(I$2,Galerias!$A$2:$A$37,0))*INDEX(Galerias!$O$2:$O$37,MATCH(I$2,Galerias!$A$2:$A$37,0))^($A11-1),0)) | ... AK11: =IF(AND(INDEX(Galerias!$M$2:$M$37,MATCH(AK$2,Galerias!$A$2:$A$37,0))<>"",$A11>INDEX(Galerias!$M$2:$M$37,MATCH(AK$2,Galerias!$A$2:$A$37,0))),"",ROUND(INDEX(Galerias!$N$2:$N$37,MATCH(AK$2,Galerias!$A$2:$A$37,0))*INDEX(Galerias!$O$2:$O$37,MATCH(AK$2,Galerias!$A$2:$A$37,0))^($A11-1),0))
A12: 10 | B12: =IF(AND(INDEX(Galerias!$M$2:$M$37,MATCH(B$2,Galerias!$A$2:$A$37,0))<>"",$A12>INDEX(Galerias!$M$2:$M$37,MATCH(B$2,Galerias!$A$2:$A$37,0))),"",ROUND(INDEX(Galerias!$N$2:$N$37,MATCH(B$2,Galerias!$A$2:$A$37,0))*INDEX(Galerias!$O$2:$O$37,MATCH(B$2,Galerias!$A$2:$A$37,0))^($A12-1),0)) | C12: =IF(AND(INDEX(Galerias!$M$2:$M$37,MATCH(C$2,Galerias!$A$2:$A$37,0))<>"",$A12>INDEX(Galerias!$M$2:$M$37,MATCH(C$2,Galerias!$A$2:$A$37,0))),"",ROUND(INDEX(Galerias!$N$2:$N$37,MATCH(C$2,Galerias!$A$2:$A$37,0))*INDEX(Galerias!$O$2:$O$37,MATCH(C$2,Galerias!$A$2:$A$37,0))^($A12-1),0)) | D12: =IF(AND(INDEX(Galerias!$M$2:$M$37,MATCH(D$2,Galerias!$A$2:$A$37,0))<>"",$A12>INDEX(Galerias!$M$2:$M$37,MATCH(D$2,Galerias!$A$2:$A$37,0))),"",ROUND(INDEX(Galerias!$N$2:$N$37,MATCH(D$2,Galerias!$A$2:$A$37,0))*INDEX(Galerias!$O$2:$O$37,MATCH(D$2,Galerias!$A$2:$A$37,0))^($A12-1),0)) | E12: =IF(AND(INDEX(Galerias!$M$2:$M$37,MATCH(E$2,Galerias!$A$2:$A$37,0))<>"",$A12>INDEX(Galerias!$M$2:$M$37,MATCH(E$2,Galerias!$A$2:$A$37,0))),"",ROUND(INDEX(Galerias!$N$2:$N$37,MATCH(E$2,Galerias!$A$2:$A$37,0))*INDEX(Galerias!$O$2:$O$37,MATCH(E$2,Galerias!$A$2:$A$37,0))^($A12-1),0)) | F12: =IF(AND(INDEX(Galerias!$M$2:$M$37,MATCH(F$2,Galerias!$A$2:$A$37,0))<>"",$A12>INDEX(Galerias!$M$2:$M$37,MATCH(F$2,Galerias!$A$2:$A$37,0))),"",ROUND(INDEX(Galerias!$N$2:$N$37,MATCH(F$2,Galerias!$A$2:$A$37,0))*INDEX(Galerias!$O$2:$O$37,MATCH(F$2,Galerias!$A$2:$A$37,0))^($A12-1),0)) | G12: =IF(AND(INDEX(Galerias!$M$2:$M$37,MATCH(G$2,Galerias!$A$2:$A$37,0))<>"",$A12>INDEX(Galerias!$M$2:$M$37,MATCH(G$2,Galerias!$A$2:$A$37,0))),"",ROUND(INDEX(Galerias!$N$2:$N$37,MATCH(G$2,Galerias!$A$2:$A$37,0))*INDEX(Galerias!$O$2:$O$37,MATCH(G$2,Galerias!$A$2:$A$37,0))^($A12-1),0)) | H12: =IF(AND(INDEX(Galerias!$M$2:$M$37,MATCH(H$2,Galerias!$A$2:$A$37,0))<>"",$A12>INDEX(Galerias!$M$2:$M$37,MATCH(H$2,Galerias!$A$2:$A$37,0))),"",ROUND(INDEX(Galerias!$N$2:$N$37,MATCH(H$2,Galerias!$A$2:$A$37,0))*INDEX(Galerias!$O$2:$O$37,MATCH(H$2,Galerias!$A$2:$A$37,0))^($A12-1),0)) | I12: =IF(AND(INDEX(Galerias!$M$2:$M$37,MATCH(I$2,Galerias!$A$2:$A$37,0))<>"",$A12>INDEX(Galerias!$M$2:$M$37,MATCH(I$2,Galerias!$A$2:$A$37,0))),"",ROUND(INDEX(Galerias!$N$2:$N$37,MATCH(I$2,Galerias!$A$2:$A$37,0))*INDEX(Galerias!$O$2:$O$37,MATCH(I$2,Galerias!$A$2:$A$37,0))^($A12-1),0)) | ... AK12: =IF(AND(INDEX(Galerias!$M$2:$M$37,MATCH(AK$2,Galerias!$A$2:$A$37,0))<>"",$A12>INDEX(Galerias!$M$2:$M$37,MATCH(AK$2,Galerias!$A$2:$A$37,0))),"",ROUND(INDEX(Galerias!$N$2:$N$37,MATCH(AK$2,Galerias!$A$2:$A$37,0))*INDEX(Galerias!$O$2:$O$37,MATCH(AK$2,Galerias!$A$2:$A$37,0))^($A12-1),0))
A13: 11 | B13: =IF(AND(INDEX(Galerias!$M$2:$M$37,MATCH(B$2,Galerias!$A$2:$A$37,0))<>"",$A13>INDEX(Galerias!$M$2:$M$37,MATCH(B$2,Galerias!$A$2:$A$37,0))),"",ROUND(INDEX(Galerias!$N$2:$N$37,MATCH(B$2,Galerias!$A$2:$A$37,0))*INDEX(Galerias!$O$2:$O$37,MATCH(B$2,Galerias!$A$2:$A$37,0))^($A13-1),0)) | C13: =IF(AND(INDEX(Galerias!$M$2:$M$37,MATCH(C$2,Galerias!$A$2:$A$37,0))<>"",$A13>INDEX(Galerias!$M$2:$M$37,MATCH(C$2,Galerias!$A$2:$A$37,0))),"",ROUND(INDEX(Galerias!$N$2:$N$37,MATCH(C$2,Galerias!$A$2:$A$37,0))*INDEX(Galerias!$O$2:$O$37,MATCH(C$2,Galerias!$A$2:$A$37,0))^($A13-1),0)) | D13: =IF(AND(INDEX(Galerias!$M$2:$M$37,MATCH(D$2,Galerias!$A$2:$A$37,0))<>"",$A13>INDEX(Galerias!$M$2:$M$37,MATCH(D$2,Galerias!$A$2:$A$37,0))),"",ROUND(INDEX(Galerias!$N$2:$N$37,MATCH(D$2,Galerias!$A$2:$A$37,0))*INDEX(Galerias!$O$2:$O$37,MATCH(D$2,Galerias!$A$2:$A$37,0))^($A13-1),0)) | E13: =IF(AND(INDEX(Galerias!$M$2:$M$37,MATCH(E$2,Galerias!$A$2:$A$37,0))<>"",$A13>INDEX(Galerias!$M$2:$M$37,MATCH(E$2,Galerias!$A$2:$A$37,0))),"",ROUND(INDEX(Galerias!$N$2:$N$37,MATCH(E$2,Galerias!$A$2:$A$37,0))*INDEX(Galerias!$O$2:$O$37,MATCH(E$2,Galerias!$A$2:$A$37,0))^($A13-1),0)) | F13: =IF(AND(INDEX(Galerias!$M$2:$M$37,MATCH(F$2,Galerias!$A$2:$A$37,0))<>"",$A13>INDEX(Galerias!$M$2:$M$37,MATCH(F$2,Galerias!$A$2:$A$37,0))),"",ROUND(INDEX(Galerias!$N$2:$N$37,MATCH(F$2,Galerias!$A$2:$A$37,0))*INDEX(Galerias!$O$2:$O$37,MATCH(F$2,Galerias!$A$2:$A$37,0))^($A13-1),0)) | G13: =IF(AND(INDEX(Galerias!$M$2:$M$37,MATCH(G$2,Galerias!$A$2:$A$37,0))<>"",$A13>INDEX(Galerias!$M$2:$M$37,MATCH(G$2,Galerias!$A$2:$A$37,0))),"",ROUND(INDEX(Galerias!$N$2:$N$37,MATCH(G$2,Galerias!$A$2:$A$37,0))*INDEX(Galerias!$O$2:$O$37,MATCH(G$2,Galerias!$A$2:$A$37,0))^($A13-1),0)) | H13: =IF(AND(INDEX(Galerias!$M$2:$M$37,MATCH(H$2,Galerias!$A$2:$A$37,0))<>"",$A13>INDEX(Galerias!$M$2:$M$37,MATCH(H$2,Galerias!$A$2:$A$37,0))),"",ROUND(INDEX(Galerias!$N$2:$N$37,MATCH(H$2,Galerias!$A$2:$A$37,0))*INDEX(Galerias!$O$2:$O$37,MATCH(H$2,Galerias!$A$2:$A$37,0))^($A13-1),0)) | I13: =IF(AND(INDEX(Galerias!$M$2:$M$37,MATCH(I$2,Galerias!$A$2:$A$37,0))<>"",$A13>INDEX(Galerias!$M$2:$M$37,MATCH(I$2,Galerias!$A$2:$A$37,0))),"",ROUND(INDEX(Galerias!$N$2:$N$37,MATCH(I$2,Galerias!$A$2:$A$37,0))*INDEX(Galerias!$O$2:$O$37,MATCH(I$2,Galerias!$A$2:$A$37,0))^($A13-1),0)) | ... AK13: =IF(AND(INDEX(Galerias!$M$2:$M$37,MATCH(AK$2,Galerias!$A$2:$A$37,0))<>"",$A13>INDEX(Galerias!$M$2:$M$37,MATCH(AK$2,Galerias!$A$2:$A$37,0))),"",ROUND(INDEX(Galerias!$N$2:$N$37,MATCH(AK$2,Galerias!$A$2:$A$37,0))*INDEX(Galerias!$O$2:$O$37,MATCH(AK$2,Galerias!$A$2:$A$37,0))^($A13-1),0))
A14: 12 | B14: =IF(AND(INDEX(Galerias!$M$2:$M$37,MATCH(B$2,Galerias!$A$2:$A$37,0))<>"",$A14>INDEX(Galerias!$M$2:$M$37,MATCH(B$2,Galerias!$A$2:$A$37,0))),"",ROUND(INDEX(Galerias!$N$2:$N$37,MATCH(B$2,Galerias!$A$2:$A$37,0))*INDEX(Galerias!$O$2:$O$37,MATCH(B$2,Galerias!$A$2:$A$37,0))^($A14-1),0)) | C14: =IF(AND(INDEX(Galerias!$M$2:$M$37,MATCH(C$2,Galerias!$A$2:$A$37,0))<>"",$A14>INDEX(Galerias!$M$2:$M$37,MATCH(C$2,Galerias!$A$2:$A$37,0))),"",ROUND(INDEX(Galerias!$N$2:$N$37,MATCH(C$2,Galerias!$A$2:$A$37,0))*INDEX(Galerias!$O$2:$O$37,MATCH(C$2,Galerias!$A$2:$A$37,0))^($A14-1),0)) | D14: =IF(AND(INDEX(Galerias!$M$2:$M$37,MATCH(D$2,Galerias!$A$2:$A$37,0))<>"",$A14>INDEX(Galerias!$M$2:$M$37,MATCH(D$2,Galerias!$A$2:$A$37,0))),"",ROUND(INDEX(Galerias!$N$2:$N$37,MATCH(D$2,Galerias!$A$2:$A$37,0))*INDEX(Galerias!$O$2:$O$37,MATCH(D$2,Galerias!$A$2:$A$37,0))^($A14-1),0)) | E14: =IF(AND(INDEX(Galerias!$M$2:$M$37,MATCH(E$2,Galerias!$A$2:$A$37,0))<>"",$A14>INDEX(Galerias!$M$2:$M$37,MATCH(E$2,Galerias!$A$2:$A$37,0))),"",ROUND(INDEX(Galerias!$N$2:$N$37,MATCH(E$2,Galerias!$A$2:$A$37,0))*INDEX(Galerias!$O$2:$O$37,MATCH(E$2,Galerias!$A$2:$A$37,0))^($A14-1),0)) | F14: =IF(AND(INDEX(Galerias!$M$2:$M$37,MATCH(F$2,Galerias!$A$2:$A$37,0))<>"",$A14>INDEX(Galerias!$M$2:$M$37,MATCH(F$2,Galerias!$A$2:$A$37,0))),"",ROUND(INDEX(Galerias!$N$2:$N$37,MATCH(F$2,Galerias!$A$2:$A$37,0))*INDEX(Galerias!$O$2:$O$37,MATCH(F$2,Galerias!$A$2:$A$37,0))^($A14-1),0)) | G14: =IF(AND(INDEX(Galerias!$M$2:$M$37,MATCH(G$2,Galerias!$A$2:$A$37,0))<>"",$A14>INDEX(Galerias!$M$2:$M$37,MATCH(G$2,Galerias!$A$2:$A$37,0))),"",ROUND(INDEX(Galerias!$N$2:$N$37,MATCH(G$2,Galerias!$A$2:$A$37,0))*INDEX(Galerias!$O$2:$O$37,MATCH(G$2,Galerias!$A$2:$A$37,0))^($A14-1),0)) | H14: =IF(AND(INDEX(Galerias!$M$2:$M$37,MATCH(H$2,Galerias!$A$2:$A$37,0))<>"",$A14>INDEX(Galerias!$M$2:$M$37,MATCH(H$2,Galerias!$A$2:$A$37,0))),"",ROUND(INDEX(Galerias!$N$2:$N$37,MATCH(H$2,Galerias!$A$2:$A$37,0))*INDEX(Galerias!$O$2:$O$37,MATCH(H$2,Galerias!$A$2:$A$37,0))^($A14-1),0)) | I14: =IF(AND(INDEX(Galerias!$M$2:$M$37,MATCH(I$2,Galerias!$A$2:$A$37,0))<>"",$A14>INDEX(Galerias!$M$2:$M$37,MATCH(I$2,Galerias!$A$2:$A$37,0))),"",ROUND(INDEX(Galerias!$N$2:$N$37,MATCH(I$2,Galerias!$A$2:$A$37,0))*INDEX(Galerias!$O$2:$O$37,MATCH(I$2,Galerias!$A$2:$A$37,0))^($A14-1),0)) | ... AK14: =IF(AND(INDEX(Galerias!$M$2:$M$37,MATCH(AK$2,Galerias!$A$2:$A$37,0))<>"",$A14>INDEX(Galerias!$M$2:$M$37,MATCH(AK$2,Galerias!$A$2:$A$37,0))),"",ROUND(INDEX(Galerias!$N$2:$N$37,MATCH(AK$2,Galerias!$A$2:$A$37,0))*INDEX(Galerias!$O$2:$O$37,MATCH(AK$2,Galerias!$A$2:$A$37,0))^($A14-1),0))
